Workbook

Sheet Final_UAE
A1: id_partner | B1: partner_sku | C1: noon_warehouse_code | D1: stock_gross | F1: Current Stock
A2: 33834 | B2: clstmon-eve-prom-p01-sn1000 | C2: W00031886A | D2: =IF(F2>=5, F2-5, IF(F2<5, 0, F2)) | E2: =VLOOKUP(B2,[1]Namshi!$A:$B,2,0) | F2: =SUMIFS('Dubai Stock'!I:I,'Dubai Stock'!H:H,Final_UAE!B:B) | H2: #N/A
A3: 33834 | B3: sw100107-30s-000401-0107-55 | C3: W00031886A | D3: =IF(F3>=5, F3-5, IF(F3<5, 0, F3)) | E3: =VLOOKUP(B3,[1]Namshi!$A:$B,2,0) | F3: =SUMIFS('Dubai Stock'!I:I,'Dubai Stock'!H:H,Final_UAE!B:B) | H3: #N/A
A4: 33834 | B4: sc50207-bab-000542-0207-45 | C4: W00031886A | D4: =IF(F4>=5, F4-5, IF(F4<5, 0, F4)) | E4: =VLOOKUP(B4,[1]Namshi!$A:$B,2,0) | F4: =SUMIFS('Dubai Stock'!I:I,'Dubai Stock'!H:H,Final_UAE!B:B) | H4: #N/A
A5: 33834 | B5: sw100404-30s-000415-0404-54 | C5: W00031886A | D5: =IF(F5>=5, F5-5, IF(F5<5, 0, F5)) | E5: =VLOOKUP(B5,[1]Namshi!$A:$B,2,0) | F5: =SUMIFS('Dubai Stock'!I:I,'Dubai Stock'!H:H,Final_UAE!B:B) | H5: #N/A
A6: 33834 | B6: su42907-30s-000463-2907-53 | C6: W00031886A | D6: =IF(F6>=5, F6-5, IF(F6<5, 0, F6)) | E6: =VLOOKUP(B6,[1]Namshi!$A:$B,2,0) | F6: =SUMIFS('Dubai Stock'!I:I,'Dubai Stock'!H:H,Final_UAE!B:B) | H6: #N/A
A7: 33834 | B7: sc50202-bab-000524-0202d-46 | C7: W00031886A | D7: =IF(F7>=5, F7-5, IF(F7<5, 0, F7)) | E7: =VLOOKUP(B7,[1]Namshi!$A:$B,2,0) | F7: =SUMIFS('Dubai Stock'!I:I,'Dubai Stock'!H:H,Final_UAE!B:B) | H7: #N/A
A8: 33834 | B8: sm52502-30s-000205-0202-55 | C8: W00031886A | D8: =IF(F8>=5, F8-5, IF(F8<5, 0, F8)) | E8: =VLOOKUP(B8,[1]Namshi!$A:$B,2,0) | F8: =SUMIFS('Dubai Stock'!I:I,'Dubai Stock'!H:H,Final_UAE!B:B) | H8: #N/A
A9: 33834 | B9: sm102906-30s-000464-2906-53 | C9: W00031886A | D9: =IF(F9>=5, F9-5, IF(F9<5, 0, F9)) | E9: =VLOOKUP(B9,[1]Namshi!$A:$B,2,0) | F9: =SUMIFS('Dubai Stock'!I:I,'Dubai Stock'!H:H,Final_UAE!B:B) | H9: #N/A
A10: 33834 | B10: sc40202-bab-000519-0202d-51 | C10: W00031886A | D10: =IF(F10>=5, F10-5, IF(F10<5, 0, F10)) | E10: =VLOOKUP(B10,[1]Namshi!$A:$B,2,0) | F10: =SUMIFS('Dubai Stock'!I:I,'Dubai Stock'!H:H,Final_UAE!B:B) | H10: #N/A
A11: 33834 | B11: clstdai-eve-pure-p05-sn0400 | C11: W00031886A | D11: =IF(F11>=5, F11-5, IF(F11<5, 0, F11)) | E11: =VLOOKUP(B11,[1]Namshi!$A:$B,2,0) | F11: =SUMIFS('Dubai Stock'!I:I,'Dubai Stock'!H:H,Final_UAE!B:B) | H11: #N/A
A12: 33834 | B12: fc40118-bab-000546-0118-47 | C12: W00031886A | D12: =IF(F12>=5, F12-5, IF(F12<5, 0, F12)) | E12: =VLOOKUP(B12,[1]Namshi!$A:$B,2,0) | F12: =SUMIFS('Dubai Stock'!I:I,'Dubai Stock'!H:H,Final_UAE!B:B) | H12: #N/A
A13: 33834 | B13: clstmon-eve-prom-p01-sn0850 | C13: W00031886A | D13: =IF(F13>=5, F13-5, IF(F13<5, 0, F13)) | E13: =VLOOKUP(B13,[1]Namshi!$A:$B,2,0) | F13: =SUMIFS('Dubai Stock'!I:I,'Dubai Stock'!H:H,Final_UAE!B:B) | H13: #N/A
A14: 33834 | B14: clstdai-eve-pure-p30-sp0400 | C14: W00031886A | D14: =IF(F14>=5, F14-5, IF(F14<5, 0, F14)) | E14: =VLOOKUP(B14,[1]Namshi!$A:$B,2,0) | F14: =SUMIFS('Dubai Stock'!I:I,'Dubai Stock'!H:H,Final_UAE!B:B) | H14: 186 | I14: 104.3
A15: 33834 | B15: sc40606-bab-000504-0606-51 | C15: W00031886A | D15: =IF(F15>=5, F15-5, IF(F15<5, 0, F15)) | E15: =VLOOKUP(B15,[1]Namshi!$A:$B,2,0) | F15: =SUMIFS('Dubai Stock'!I:I,'Dubai Stock'!H:H,Final_UAE!B:B) | H15: #N/A
A16: 33834 | B16: sc20907-bab-000517-0907d-43 | C16: W00031886A | D16: =IF(F16>=5, F16-5, IF(F16<5, 0, F16)) | E16: =VLOOKUP(B16,[1]Namshi!$A:$B,2,0) | F16: =SUMIFS('Dubai Stock'!I:I,'Dubai Stock'!H:H,Final_UAE!B:B) | H16: #N/A
A17: 33834 | B17: clstdai-lay-cont-p90-dazzle-black-sp0000 | C17: W00031886A | D17: =IF(F17>=5, F17-5, IF(F17<5, 0, F17)) | E17: =VLOOKUP(B17,[1]Namshi!$A:$B,2,0) | F17: =SUMIFS('Dubai Stock'!I:I,'Dubai Stock'!H:H,Final_UAE!B:B) | H17: #N/A
A18: 33834 | B18: sw102304-30s-000415-2304-54 | C18: W00031886A | D18: =IF(F18>=5, F18-5, IF(F18<5, 0, F18)) | E18: =VLOOKUP(B18,[1]Namshi!$A:$B,2,0) | F18: =SUMIFS('Dubai Stock'!I:I,'Dubai Stock'!H:H,Final_UAE!B:B) | H18: #N/A
A19: 33834 | B19: sm51406-30s-000466-1406-52 | C19: W00031886A | D19: =IF(F19>=5, F19-5, IF(F19<5, 0, F19)) | E19: =VLOOKUP(B19,[1]Namshi!$A:$B,2,0) | F19: =SUMIFS('Dubai Stock'!I:I,'Dubai Stock'!H:H,Final_UAE!B:B) | H19: #N/A
A20: 33834 | B20: clstmon-eve-prom-p01-sn0125 | C20: W00031886A | D20: =IF(F20>=5, F20-5, IF(F20<5, 0, F20)) | E20: =VLOOKUP(B20,[1]Namshi!$A:$B,2,0) | F20: =SUMIFS('Dubai Stock'!I:I,'Dubai Stock'!H:H,Final_UAE!B:B) | H20: #N/A
A21: 33834 | B21: su20107-30s-000461-0107-54 | C21: W00031886A | D21: =IF(F21>=5, F21-5, IF(F21<5, 0, F21)) | E21: =VLOOKUP(B21,[1]Namshi!$A:$B,2,0) | F21: =SUMIFS('Dubai Stock'!I:I,'Dubai Stock'!H:H,Final_UAE!B:B) | H21: #N/A
A22: 33834 | B22: sc20607-bab-000526-0607-43 | C22: W00031886A | D22: =IF(F22>=5, F22-5, IF(F22<5, 0, F22)) | E22: =VLOOKUP(B22,[1]Namshi!$A:$B,2,0) | F22: =SUMIFS('Dubai Stock'!I:I,'Dubai Stock'!H:H,Final_UAE!B:B) | H22: #N/A
A23: 33834 | B23: sc30804-bab-00536-0804d-45 | C23: W00031886A | D23: =IF(F23>=5, F23-5, IF(F23<5, 0, F23)) | E23: =VLOOKUP(B23,[1]Namshi!$A:$B,2,0) | F23: =SUMIFS('Dubai Stock'!I:I,'Dubai Stock'!H:H,Final_UAE!B:B) | H23: #N/A
A24: 33834 | B24: sw30107-30s-000418-0107-52 | C24: W00031886A | D24: =IF(F24>=5, F24-5, IF(F24<5, 0, F24)) | E24: =VLOOKUP(B24,[1]Namshi!$A:$B,2,0) | F24: =SUMIFS('Dubai Stock'!I:I,'Dubai Stock'!H:H,Final_UAE!B:B) | H24: #N/A
A25: 33834 | B25: sm110107-30s-000451-0107-49 | C25: W00031886A | D25: =IF(F25>=5, F25-5, IF(F25<5, 0, F25)) | E25: =VLOOKUP(B25,[1]Namshi!$A:$B,2,0) | F25: =SUMIFS('Dubai Stock'!I:I,'Dubai Stock'!H:H,Final_UAE!B:B) | H25: #N/A
A26: 33834 | B26: sc51407-bab-00537-1407d-46 | C26: W00031886A | D26: =IF(F26>=5, F26-5, IF(F26<5, 0, F26)) | E26: =VLOOKUP(B26,[1]Namshi!$A:$B,2,0) | F26: =SUMIFS('Dubai Stock'!I:I,'Dubai Stock'!H:H,Final_UAE!B:B) | H26: #N/A
... A28: 33834 | B28: sm100106-30s-000407-0106-52 | C28: W00031886A | D28: =IF(F28>=5, F28-5, IF(F28<5, 0, F28)) | E28: =VLOOKUP(B28,[1]Namshi!$A:$B,2,0) | F28: =SUMIFS('Dubai Stock'!I:I,'Dubai Stock'!H:H,Final_UAE!B:B) | H28: #N/A
A29: 33834 | B29: clstdai-eve-pure-p30-sp0050 | C29: W00031886A | D29: =IF(F29>=5, F29-5, IF(F29<5, 0, F29)) | E29: =VLOOKUP(B29,[1]Namshi!$A:$B,2,0) | F29: =SUMIFS('Dubai Stock'!I:I,'Dubai Stock'!H:H,Final_UAE!B:B) | H29: 186 | I29: 104.3
A30: 33834 | B30: sc21007-bab-000526-1007-43 | C30: W00031886A | D30: =IF(F30>=5, F30-5, IF(F30<5, 0, F30)) | E30: =VLOOKUP(B30,[1]Namshi!$A:$B,2,0) | F30: =SUMIFS('Dubai Stock'!I:I,'Dubai Stock'!H:H,Final_UAE!B:B) | H30: #N/A
A31: 33834 | B31: sc21007-bab-000544-1007-44 | C31: W00031886A | D31: =IF(F31>=5, F31-5, IF(F31<5, 0, F31)) | E31: =VLOOKUP(B31,[1]Namshi!$A:$B,2,0) | F31: =SUMIFS('Dubai Stock'!I:I,'Dubai Stock'!H:H,Final_UAE!B:B) | H31: #N/A
A32: 33834 | B32: sc50107-bab-00538-0107d-51 | C32: W00031886A | D32: =IF(F32>=5, F32-5, IF(F32<5, 0, F32)) | E32: =VLOOKUP(B32,[1]Namshi!$A:$B,2,0) | F32: =SUMIFS('Dubai Stock'!I:I,'Dubai Stock'!H:H,Final_UAE!B:B) | H32: #N/A
A33: 33834 | B33: sc21407-bab-000547-1407-47 | C33: W00031886A | D33: =IF(F33>=5, F33-5, IF(F33<5, 0, F33)) | E33: =VLOOKUP(B33,[1]Namshi!$A:$B,2,0) | F33: =SUMIFS('Dubai Stock'!I:I,'Dubai Stock'!H:H,Final_UAE!B:B) | H33: #N/A
A34: 33834 | B34: sm100702-30s-000410-0702-55 | C34: W00031886A | D34: =IF(F34>=5, F34-5, IF(F34<5, 0, F34)) | E34: =VLOOKUP(B34,[1]Namshi!$A:$B,2,0) | F34: =SUMIFS('Dubai Stock'!I:I,'Dubai Stock'!H:H,Final_UAE!B:B) | H34: #N/A
A35: 33834 | B35: sw40106-30s-000400-0106-53 | C35: W00031886A | D35: =IF(F35>=5, F35-5, IF(F35<5, 0, F35)) | E35: =VLOOKUP(B35,[1]Namshi!$A:$B,2,0) | F35: =SUMIFS('Dubai Stock'!I:I,'Dubai Stock'!H:H,Final_UAE!B:B) | H35: #N/A
A36: 33834 | B36: clstmon-eve-prom-p01-sn0400 | C36: W00031886A | D36: =IF(F36>=5, F36-5, IF(F36<5, 0, F36)) | E36: =VLOOKUP(B36,[1]Namshi!$A:$B,2,0) | F36: =SUMIFS('Dubai Stock'!I:I,'Dubai Stock'!H:H,Final_UAE!B:B) | H36: #N/A
A37: 33834 | B37: sw32607-30s-000412-2607-50 | C37: W00031886A | D37: =IF(F37>=5, F37-5, IF(F37<5, 0, F37)) | E37: =VLOOKUP(B37,[1]Namshi!$A:$B,2,0) | F37: =SUMIFS('Dubai Stock'!I:I,'Dubai Stock'!H:H,Final_UAE!B:B) | H37: #N/A
A38: 33834 | B38: clstdai-eve-pure-p05-sn0100 | C38: W00031886A | D38: =IF(F38>=5, F38-5, IF(F38<5, 0, F38)) | E38: =VLOOKUP(B38,[1]Namshi!$A:$B,2,0) | F38: =SUMIFS('Dubai Stock'!I:I,'Dubai Stock'!H:H,Final_UAE!B:B) | H38: #N/A
A39: 33834 | B39: clstdai-eve-pure-p05-sn0375 | C39: W00031886A | D39: =IF(F39>=5, F39-5, IF(F39<5, 0, F39)) | E39: =VLOOKUP(B39,[1]Namshi!$A:$B,2,0) | F39: =SUMIFS('Dubai Stock'!I:I,'Dubai Stock'!H:H,Final_UAE!B:B) | H39: #N/A
A40: 33834 | B40: sm50107-30s-000466-0107-52 | C40: W00031886A | D40: =IF(F40>=5, F40-5, IF(F40<5, 0, F40)) | E40: =VLOOKUP(B40,[1]Namshi!$A:$B,2,0) | F40: =SUMIFS('Dubai Stock'!I:I,'Dubai Stock'!H:H,Final_UAE!B:B) | H40: #N/A
A41: 33834 | B41: sw32404-30s-000458-2404-56 | C41: W00031886A | D41: =IF(F41>=5, F41-5, IF(F41<5, 0, F41)) | E41: =VLOOKUP(B41,[1]Namshi!$A:$B,2,0) | F41: =SUMIFS('Dubai Stock'!I:I,'Dubai Stock'!H:H,Final_UAE!B:B) | H41: #N/A
...
