Workbook

Sheet Noon UAE
A1: country_code | B1: id_partner | C1: partner_sku | D1: noon_warehouse_code | E1: stock_gross | F1: processing_time | H1: Current Stock
A2: ae | B2: 33834 | C2: costdai-acu-dffr-p30-honey-sn0050 | D2: W00031886A | E2: =IF(H2>=2, H2-2, IF(H2<2, 0, H2)) | F2: 1_day | H2: =SUMIFS('Dubai Stock'!I:I,'Dubai Stock'!H:H,'Noon UAE'!C:C) | J2: #N/A
A3: ae | B3: 33834 | C3: sm10304-30s-000456-0304-57 | D3: W00031886A | E3: =IF(H3>=2, H3-2, IF(H3<2, 0, H3)) | F3: 1_day | H3: =SUMIFS('Dubai Stock'!I:I,'Dubai Stock'!H:H,'Noon UAE'!C:C) | J3: 449 | K3: 314.03006
A4: ae | B4: 33834 | C4: sm11207-30s-000456-1207-57 | D4: W00031886A | E4: =IF(H4>=2, H4-2, IF(H4<2, 0, H4)) | F4: 1_day | H4: =SUMIFS('Dubai Stock'!I:I,'Dubai Stock'!H:H,'Noon UAE'!C:C) | J4: 449 | K4: 314.03006
A5: ae | B5: 33834 | C5: sm100406-30s-000410-0406-55 | D5: W00031886A | E5: =IF(H5>=2, H5-2, IF(H5<2, 0, H5)) | F5: 1_day | H5: =SUMIFS('Dubai Stock'!I:I,'Dubai Stock'!H:H,'Noon UAE'!C:C) | J5: #N/A
A6: ae | B6: 33834 | C6: sw52404-30s-000431-2404-50 | D6: W00031886A | E6: =IF(H6>=2, H6-2, IF(H6<2, 0, H6)) | F6: 1_day | H6: =SUMIFS('Dubai Stock'!I:I,'Dubai Stock'!H:H,'Noon UAE'!C:C) | J6: 449 | K6: 269.04008
A7: ae | B7: 33834 | C7: saccase-30s-case104-brn-bge-caramel-brown | D7: W00031886A | E7: =IF(H7>=2, H7-2, IF(H7<2, 0, H7)) | F7: 1_day | H7: =SUMIFS('Dubai Stock'!I:I,'Dubai Stock'!H:H,'Noon UAE'!C:C) | J7: #N/A
A8: ae | B8: 33834 | C8: saccase-30s-case104-nvy-bge-navy-blue | D8: W00031886A | E8: =IF(H8>=2, H8-2, IF(H8<2, 0, H8)) | F8: 1_day | H8: =SUMIFS('Dubai Stock'!I:I,'Dubai Stock'!H:H,'Noon UAE'!C:C) | J8: #N/A
A9: ae | B9: 33834 | C9: saccase-30s-case104-blk-blk-black | D9: W00031886A | E9: =IF(H9>=2, H9-2, IF(H9<2, 0, H9)) | F9: 1_day | H9: =SUMIFS('Dubai Stock'!I:I,'Dubai Stock'!H:H,'Noon UAE'!C:C) | J9: #N/A
A10: ae | B10: 33834 | C10: sacchan-30s-chain101-blk-black | D10: W00031886A | E10: =IF(H10>=2, H10-2, IF(H10<2, 0, H10)) | F10: 1_day | H10: =SUMIFS('Dubai Stock'!I:I,'Dubai Stock'!H:H,'Noon UAE'!C:C) | J10: #N/A
A11: ae | B11: 33834 | C11: sacchan-30s-chain101-gry-fleek-gunmetal | D11: W00031886A | E11: =IF(H11>=2, H11-2, IF(H11<2, 0, H11)) | F11: 1_day | H11: =SUMIFS('Dubai Stock'!I:I,'Dubai Stock'!H:H,'Noon UAE'!C:C) | J11: #N/A
A12: ae | B12: 33834 | C12: sacchan-30s-chain105-gpl-gold | D12: W00031886A | E12: =IF(H12>=2, H12-2, IF(H12<2, 0, H12)) | F12: 1_day | H12: =SUMIFS('Dubai Stock'!I:I,'Dubai Stock'!H:H,'Noon UAE'!C:C) | J12: #N/A
A13: ae | B13: 33834 | C13: sacchan-30s-chain108-blk-inu-black | D13: W00031886A | E13: =IF(H13>=2, H13-2, IF(H13<2, 0, H13)) | F13: 1_day | H13: =SUMIFS('Dubai Stock'!I:I,'Dubai Stock'!H:H,'Noon UAE'!C:C) | J13: #N/A
A14: ae | B14: 33834 | C14: sacchan-30s-chain122-svr-isla-silver | D14: W00031886A | E14: =IF(H14>=2, H14-2, IF(H14<2, 0, H14)) | F14: 1_day | H14: =SUMIFS('Dubai Stock'!I:I,'Dubai Stock'!H:H,'Noon UAE'!C:C) | J14: #N/A
A15: ae | B15: 33834 | C15: sacchan-30s-chain122-gld-isla-gold | D15: W00031886A | E15: =IF(H15>=2, H15-2, IF(H15<2, 0, H15)) | F15: 1_day | H15: =SUMIFS('Dubai Stock'!I:I,'Dubai Stock'!H:H,'Noon UAE'!C:C) | J15: #N/A
A16: ae | B16: 33834 | C16: sacchan-30s-chain115-gry-kali-gray | D16: W00031886A | E16: =IF(H16>=2, H16-2, IF(H16<2, 0, H16)) | F16: 1_day | H16: =SUMIFS('Dubai Stock'!I:I,'Dubai Stock'!H:H,'Noon UAE'!C:C) | J16: #N/A
A17: ae | B17: 33834 | C17: sacchan-30s-kali-black | D17: W00031886A | E17: =IF(H17>=2, H17-2, IF(H17<2, 0, H17)) | F17: 1_day | H17: =SUMIFS('Dubai Stock'!I:I,'Dubai Stock'!H:H,'Noon UAE'!C:C) | J17: #N/A
A18: ae | B18: 33834 | C18: sm50107-30s-000466-0107-52 | D18: W00031886A | E18: =IF(H18>=2, H18-2, IF(H18<2, 0, H18)) | F18: 1_day | H18: =SUMIFS('Dubai Stock'!I:I,'Dubai Stock'!H:H,'Noon UAE'!C:C) | J18: 399 | K18: 279
A19: ae | B19: 33834 | C19: sm100107-30s-000447-0107-53 | D19: W00031886A | E19: =IF(H19>=2, H19-2, IF(H19<2, 0, H19)) | F19: 1_day | H19: =SUMIFS('Dubai Stock'!I:I,'Dubai Stock'!H:H,'Noon UAE'!C:C) | J19: 399 | K19: 279.03341
A20: ae | B20: 33834 | C20: sacchan-30s-chain104-gpl-gold | D20: W00031886A | E20: =IF(H20>=2, H20-2, IF(H20<2, 0, H20)) | F20: 1_day | H20: =SUMIFS('Dubai Stock'!I:I,'Dubai Stock'!H:H,'Noon UAE'!C:C) | J20: #N/A
A21: ae | B21: 33834 | C21: sw62907-30s-000435-2907-54 | D21: W00031886A | E21: =IF(H21>=2, H21-2, IF(H21<2, 0, H21)) | F21: 1_day | H21: =SUMIFS('Dubai Stock'!I:I,'Dubai Stock'!H:H,'Noon UAE'!C:C) | J21: 449 | K21: 269.04008
A22: ae | B22: 33834 | C22: sm100107-30s-000444-0107-53 | D22: W00031886A | E22: =IF(H22>=2, H22-2, IF(H22<2, 0, H22)) | F22: 1_day | H22: =SUMIFS('Dubai Stock'!I:I,'Dubai Stock'!H:H,'Noon UAE'!C:C) | J22: 399 | K22: 239.04454
A23: ae | B23: 33834 | C23: sm50107-30s-000217-0107-54 | D23: W00031886A | E23: =IF(H23>=2, H23-2, IF(H23<2, 0, H23)) | F23: 1_day | H23: =SUMIFS('Dubai Stock'!I:I,'Dubai Stock'!H:H,'Noon UAE'!C:C) | J23: 399 | K23: 279
A24: ae | B24: 33834 | C24: su100606-30s-000277-2102-52 | D24: W00031886A | E24: =IF(H24>=2, H24-2, IF(H24<2, 0, H24)) | F24: 1_day | H24: =SUMIFS('Dubai Stock'!I:I,'Dubai Stock'!H:H,'Noon UAE'!C:C) | J24: #N/A
A25: ae | B25: 33834 | C25: sc50904-bab-000503-0904-46 | D25: W00031886A | E25: =IF(H25>=2, H25-2, IF(H25<2, 0, H25)) | F25: 1_day | H25: =SUMIFS('Dubai Stock'!I:I,'Dubai Stock'!H:H,'Noon UAE'!C:C) | J25: 199 | K25: 139
A26: ae | B26: 33834 | C26: sc50202-bab-000503-0202-46 | D26: W00031886A | E26: =IF(H26>=2, H26-2, IF(H26<2, 0, H26)) | F26: 1_day | H26: =SUMIFS('Dubai Stock'!I:I,'Dubai Stock'!H:H,'Noon UAE'!C:C) | J26: 199 | K26: 139
A27: ae | B27: 33834 | C27: sc50107-bab-000503-0107-46 | D27: W00031886A | E27: =IF(H27>=2, H27-2, IF(H27<2, 0, H27)) | F27: 1_day | H27: =SUMIFS('Dubai Stock'!I:I,'Dubai Stock'!H:H,'Noon UAE'!C:C) | J27: 199 | K27: 139
A28: ae | B28: 33834 | C28: sc51402-bab-000503-1402-46 | D28: W00031886A | E28: =IF(H28>=2, H28-2, IF(H28<2, 0, H28)) | F28: 1_day | H28: =SUMIFS('Dubai Stock'!I:I,'Dubai Stock'!H:H,'Noon UAE'!C:C) | J28: 199 | K28: 139
A29: ae | B29: 33834 | C29: sc50207-bab-000503-0207-46 | D29: W00031886A | E29: =IF(H29>=2, H29-2, IF(H29<2, 0, H29)) | F29: 1_day | H29: =SUMIFS('Dubai Stock'!I:I,'Dubai Stock'!H:H,'Noon UAE'!C:C) | J29: 199 | K29: 139
A30: ae | B30: 33834 | C30: sc50107-bab-000504-0107-51 | D30: W00031886A | E30: =IF(H30>=2, H30-2, IF(H30<2, 0, H30)) | F30: 1_day | H30: =SUMIFS('Dubai Stock'!I:I,'Dubai Stock'!H:H,'Noon UAE'!C:C) | J30: 199 | K30: 139
A31: ae | B31: 33834 | C31: su101204-bla-000355-1204-51 | D31: W00031886A | E31: =IF(H31>=2, H31-2, IF(H31<2, 0, H31)) | F31: 1_day | H31: =SUMIFS('Dubai Stock'!I:I,'Dubai Stock'!H:H,'Noon UAE'!C:C) | J31: 299 | K31: 209
A32: ae | B32: 33834 | C32: su102904-bla-000334-2904-56 | D32: W00031886A | E32: =IF(H32>=2, H32-2, IF(H32<2, 0, H32)) | F32: 1_day | H32: =SUMIFS('Dubai Stock'!I:I,'Dubai Stock'!H:H,'Noon UAE'!C:C) | J32: 299 | K32: 179
A33: ae | B33: 33834 | C33: sm101804-bla-000336-1804-54 | D33: W00031886A | E33: =IF(H33>=2, H33-2, IF(H33<2, 0, H33)) | F33: 1_day | H33: =SUMIFS('Dubai Stock'!I:I,'Dubai Stock'!H:H,'Noon UAE'!C:C) | J33: 299 | K33: 179
A34: ae | B34: 33834 | C34: sm40107-bla-000339-0107-57 | D34: W00031886A | E34: =IF(H34>=2, H34-2, IF(H34<2, 0, H34)) | F34: 1_day | H34: =SUMIFS('Dubai Stock'!I:I,'Dubai Stock'!H:H,'Noon UAE'!C:C) | J34: 299 | K34: 179
A35: ae | B35: 33834 | C35: sw60404-bla-000300-0404-53 | D35: W00031886A | E35: =IF(H35>=2, H35-2, IF(H35<2, 0, H35)) | F35: 1_day | H35: =SUMIFS('Dubai Stock'!I:I,'Dubai Stock'!H:H,'Noon UAE'!C:C) | J35: #N/A
A36: ae | B36: 33834 | C36: sm20107-30s-000219-0107-50 | D36: W00031886A | E36: =IF(H36>=2, H36-2, IF(H36<2, 0, H36)) | F36: 1_day | H36: =SUMIFS('Dubai Stock'!I:I,'Dubai Stock'!H:H,'Noon UAE'!C:C) | J36: #N/A
A37: ae | B37: 33834 | C37: clstbiw-acu-oasy-p06-sp0750 | D37: W00031886A | E37: =IF(H37>=2, H37-2, IF(H37<2, 0, H37)) | F37: 1_day | H37: =SUMIFS('Dubai Stock'!I:I,'Dubai Stock'!H:H,'Noon UAE'!C:C) | J37: #N/A
A38: ae | B38: 33834 | C38: clstbiw-acu-oasy-p06-sp0700 | D38: W00031886A | E38: =IF(H38>=2, H38-2, IF(H38<2, 0, H38)) | F38: 1_day | H38: =SUMIFS('Dubai Stock'!I:I,'Dubai Stock'!H:H,'Noon UAE'!C:C) | J38: #N/A
A39: ae | B39: 33834 | C39: clstbiw-acu-oasy-p06-sp0200 | D39: W00031886A | E39: =IF(H39>=2, H39-2, IF(H39<2, 0, H39)) | F39: 1_day | H39: =SUMIFS('Dubai Stock'!I:I,'Dubai Stock'!H:H,'Noon UAE'!C:C) | J39: #N/A
A40: ae | B40: 33834 | C40: clstbiw-acu-oasy-p06-sp0475 | D40: W00031886A | E40: =IF(H40>=2, H40-2, IF(H40<2, 0, H40)) | F40: 1_day | H40: =SUMIFS('Dubai Stock'!I:I,'Dubai Stock'!H:H,'Noon UAE'!C:C) | J40: #N/A
...
